Workbook

Sheet raw_data
A1: student_id | B1: branch | C1: track | D1: gender | E1: age | F1: study_hours_week | G1: commute_minutes | H1: sleep_hours | I1: projects_submitted | J1: satisfaction_1to5 | K1: has_laptop | L1: transport | M1: pets_at_home | N1: favorite_sport | O1: final_score
A2: ITI-1031 | B2: Cairo | C2: Data Science | D2: Male | E2: 21 | F2: 16.5 | G2: 34.1 | H2: 5.5 | I2: 2 | J2: 3 | K2: Yes | L2: Car | M2: 0 | N2: Swimming | O2: 79.3
A3: ITI-1117 | B3: Assiut | C3: Data Science | D3: Female | E3: 29 | F3: 25.1 hours | G3: 5.0 | H3: 6.6 | I3: 3 | J3: 4 | K3: Yes | L3: Metro | M3: 1 | N3: Football | O3: 91.7
A4: ITI-1080 | B4: Cairo | C4: Data Science | D4: Male | E4: 25 | F4: 14.1 | G4: 73.2 | H4: 7.7 | I4: 0 | J4: 4 | K4: Yes | L4: Bus | M4: 0 | O4: 79.3
A5: ITI-1128 | B5: Cairo | C5: Web Development | D5: Female | E5: 25 | F5: -5 | G5: 13.7 | H5: 6.3 | I5: 2 | J5: 4 | K5: Yes | L5: Metro | M5: 1 | O5: 90.6
A6: ITI-1197 | B6: Menoufia | C6: Web Development | D6: Male | E6: 25 | F6: 19.9 | G6: 17.2 | H6: 6.9 | I6: 3 | J6: 3 | K6: No | L6: Car | M6: 0 | N6: none | O6: 86.8
A7: ITI-1138 | B7: Cairo | C7: UI/UX | D7: Male | E7: 22 | F7: 8.5 | G7: 29.6 | H7: 5.2 | I7: 4 | J7: 2 | K7: Yes | L7: Microbus | M7: 1 | N7: Running | O7: 59.1
A8: ITI-1210 | B8: Cairo | C8: Data Science | D8: Male | E8: 21 | F8: 20.4 | G8: 56.1 | H8: 6.2 | I8: 3 | J8: 5 | K8: Yes | L8: Bus | M8: 0 | N8: Football | O8: 92.5
A9: ITI-1046 | B9: Cairo | C9: Data Science | D9: Female | E9: 23 | F9: 14.0 | G9: 51.7 | H9: 7.4 | I9: 3 | J9: 3 | K9: Yes | L9: Bus | M9: 3 | N9: Football | O9: 72.6
A10: ITI-1159 | B10: Assiut | C10: Data Science | D10: Male | E10: 20 | F10: 17.6 | G10: 21.8 | H10: 6.1 | I10: 5 | J10: 4 | K10: Yes | L10: Walk | M10: 1 | N10: Swimming | O10: 88.6
A11: ITI-1248 | B11: Alexandria | C11: Data Science | D11: Male | E11: 22 | F11: 18.7 | G11: 15.0 | H11: 7.3 | I11: 4 | J11: 4 | K11: No | L11: Microbus | M11: 0 | N11: Basketball | O11: 84.9
A12: ITI-1184 | B12: Mansoura | C12: Web Development | D12: Female | E12: 23 | F12: 12.2 | G12: 58.2 | H12: 7.3 | I12: 7 | J12: 3 | K12: 1 | L12: Microbus | M12: 2 | O12: 71.9
A13: ITI-1042 | B13: cairo | C13: Data Science | D13: Male | E13: 27 | F13: 21.9 | G13: 22.8 | H13: 6.7 | I13: 6 | J13: 5 | K13: Yes | L13: Bus | M13: 0 | N13: Basketball | O13: 87.7
A14: ITI-1228 | B14: alexandria | C14: Web Development | D14: Female | E14: 20 | G14: 15.7 | H14: 6.1 | I14: 2 | J14: 5 | K14: Yes | L14: Car | M14: 0 | N14: Football | O14: 55,6
A15: ITI-1083 | B15: Cairo | C15: Data Science | D15: Male | E15: 23 | F15: 12.3 | G15: 39.2 | H15: 6.3 | I15: 5 | J15: 5 | K15: Yes | L15: Bus | M15: 0 | N15: Running | O15: 78.6
A16: ITI-1166 | B16: Alexandria | C16: web development | D16: Male | E16: 26 | F16: 13.1 hours | G16: 63.8 | H16: 7.9 | I16: 1 | J16: 5 | K16: Y | L16: Bus | M16: 0 | N16: none | O16: 74.3
A17: ITI-1195 | B17: Mansoura | C17: UI/UX | D17: Female | E17: 25 | F17: 14.7 | G17: 13.6 | H17: 6.9 | I17: 4 | J17: 3 | K17: Yes | L17: Bus | M17: 0 | O17: 77.2
A18: ITI-1227 | B18: Alexandria | C18: Web Development | D18: Male | E18: 22 | F18: 16.6 | G18: 59.1 | H18: 7.5 | I18: 2 | J18: 3 | K18: Yes | L18: Bus | M18: 0 | N18: Basketball | O18: 66.8
A19: ITI-1147 | B19: Cairo | C19: Data Science | D19: Female | E19: 20 | F19: 18.6 | G19: 44.3 | H19: 7 | I19: 6 | J19: 2 | K19: Yes | L19: Metro | M19: 0 | N19: Football | O19: 83.7
A20: ITI-1105 | B20: Alexandria | C20: Web Development | D20: Female | E20: 25 | F20: 25.9 | G20: 22.4 | H20: 7.1 | I20: 4 | J20: 3 | K20: Yes | L20: bus | M20: 0 | N20: Running | O20: 87.4
A21: ITI-1061 | B21: Assiut | C21: data science | D21: Male | E21: 23 | F21: 24.3 | G21: 5.0 | H21: 6 | I21: 5 | J21: 5 | K21: No | L21: Metro | M21: 1 | N21: Football | O21: 91.6
A22: ITI-1222 | B22: Cairo | C22: Data Science | D22: Male | E22: 21 | F22: 21.2 | G22: 30.3 | H22: 7.2 | I22: 6 | J22: 5 | K22: Yes | L22: Walk | M22: 0 | N22: Football | O22: 90.0
A23: ITI-1109 | B23: Menoufia | C23: Data Science | D23: Male | E23: 23 | F23: 9.5 | G23: 43.9 | H23: 6.6 | I23: 3 | J23: 5 | K23: Yes | L23: Microbus | M23: 1 | N23: Basketball | O23: 77.0
A24: ITI-1047 | B24: Cairo | C24: Data Science | D24: Female | E24: 22 | F24: 6.4 | G24: 17.1 | H24: 7 | I24: 4 | J24: 3 | K24: Yes | L24: METRO | M24: 0 | N24: Football | O24: 66.9
A25: ITI-1043 | B25: Cairo | C25: UI/UX | D25: Female | E25: 24 | F25: 13.7 | G25: 111.7 | H25: 6.9 | I25: 1 | J25: 3 | K25: 1 | L25: Bus | M25: 2 | O25: 69.4
A26: ITI-1186 | B26: Cairo | C26: Embedded Systems | D26: Male | E26: 21 | F26: 18.3 | G26: 66.4 | H26: 8.7 | I26: 4 | J26: 3 | K26: Yes | L26: Bus | M26: 0 | O26: 85.7
A27: ITI-1010 | B27: Menoufia | C27: Data Science | D27: Female | E27: 24 | F27: 25.7 | G27: 10.8 | H27: 6.1 | I27: 3 | J27: 4 | K27: Yes | L27: Walk | M27: 2 | N27: No sport | O27: 80.3
A28: ITI-1023 | B28: Menoufia | C28: Web Development | D28: Male | E28: 24 | F28: 21.5 | G28: 8.4 | H28: 7 | I28: 7 | J28: 5 | K28: Yes | L28: Bus | M28: 1 | N28: none | O28: 91.7
A29: ITI-1200 | B29: Alexandria | C29: Web Development | D29: Male | E29: 23 | G29: 35.2 | H29: 6.6 | I29: 3 | J29: 3 | K29: Yes | L29: Walk | M29: 1 | N29: Football | O29: 75.3
A30: ITI-1110 | B30: Mansoura | C30: Web Development | D30: Female | E30: 20 | F30: 9.3 | G30: 31 min | H30: 6.7 | I30: 1 | J30: 4 | K30: No | L30: Car | M30: 0 | N30: Running | O30: 74.6
A31: ITI-1025 | B31: Mansoura | C31: Data Science | D31: Male | E31: 20 | F31: 17.7 | G31: 43.8 | H31: 6.8 | I31: 7 | J31: 4 | K31: Yes | L31: Walk | M31: 0 | N31: Swimming | O31: 77.2
A32: ITI-1114 | B32: Mansoura | C32: Data Science | D32: Female | E32: 29 | F32: 18.8 | G32: 16.2 | H32: 5.7 | I32: 0 | J32: 3 | K32: No | L32: Metro | M32: 1 | N32: Running | O32: 76.6
A33: ITI-1069 | B33: Cairo | C33: UI/UX | D33: Male | E33: 24 | F33: 16.5 | G33: 83 min | H33: 8.1 | I33: 2 | J33: 4 | K33: Yes | L33: Metro | M33: 0 | O33: 90.0
A34: ITI-1145 | B34: Menoufia | C34: Web Development | D34: Male | E34: 150 | F34: 15.7 | G34: 52.6 | H34: 6.4 | I34: 2 | J34: 3 | K34: No | L34: Bus | M34: 1 | N34: Swimming | O34: 85.1
A35: ITI-1225 | B35: Mansora | C35: Data Science | D35: Male | E35: 25 | F35: 17.9 | G35: 12.2 | H35: 6.3 | I35: 3 | J35: 4 | K35: Yes | L35: Bus | M35: 0 | N35: Swimming | O35: 84.2
A36: ITI-1253 | B36: Cairo | C36: UI/UX | D36: Female | E36: 28 | F36: 9.8 | G36: 27.2 | H36: 7.8 | I36: 2 | J36: 2 | K36: Yes | L36: micro bus | M36: 0 | N36: Running | O36: 71.0
A37: ITI-1007 | B37: Alexandria | C37: Embedded Systems | D37: Male | E37: 24 | F37: 19.7 | G37: 31.9 | H37: 7.6 | I37: 1 | J37: 4 | K37: Yes | L37: Bus | M37: 0 | N37: Running | O37: 90.3
A38: ITI-1121 | B38: Cairo | C38: Data Science | D38: Female | E38: 23 | F38: 12.7 | G38: 11.6 | H38: 6 | I38: 5 | J38: 2 | K38: No | L38: Microbus | M38: 0 | N38: Football | O38: 78.3
A39: ITI-1068 | B39: Menoufia | C39: Data Science | D39: Male | E39: 25 | F39: 16.6 | G39: 44.1 | H39: 6.6 | I39: 3 | J39: 5 | K39: No | L39: Bus | M39: 0 | N39: Football | O39: 79.5
A40: ITI-1120 | B40: Assiut | C40: Data Science | D40: Female | E40: 21 | F40: 14.1 | G40: 18.5 | H40: 8.1 | I40: 3 | J40: 5 | K40: Yes | L40: Car | M40: 0 | N40: Football | O40: 71.9
...

Sheet cleaned_data
A1: student_id | B1: branch | C1: track | D1: gender | E1: age | F1: study_hours_week | G1: commute_minutes | H1: sleep_hours | I1: projects_submitted | J1: satisfaction_1to5 | K1: has_laptop | L1: transport | M1: pets_at_home | N1: favorite_sport | O1: final_score
A2: ITI-1031 | B2: Cairo | C2: Data Science | D2: Male | E2: 21 | F2: 16.5 | G2: 34.1 | H2: 5.5 | I2: 2 | J2: 3 | K2: Yes | L2: Car | M2: 0 | N2: Swimming | O2: 79.3
A3: ITI-1117 | B3: Assiut | C3: Data Science | D3: Female | E3: 29 | F3: 25.1 | G3: 5 | H3: 6.6 | I3: 3 | J3: 4 | K3: Yes | L3: Metro | M3: 1 | N3: Football | O3: 91.7
A4: ITI-1080 | B4: Cairo | C4: Data Science | D4: Male | E4: 25 | F4: 14.1 | G4: 73.2 | H4: 7.7 | I4: 0 | J4: 4 | K4: Yes | L4: Bus | M4: 0 | O4: 79.3
A5: ITI-1128 | B5: Cairo | C5: Web Development | D5: Female | E5: 25 | G5: 13.7 | H5: 6.3 | I5: 2 | J5: 4 | K5: Yes | L5: Metro | M5: 1 | O5: 90.6
A6: ITI-1197 | B6: Menoufia | C6: Web Development | D6: Male | E6: 25 | F6: 19.9 | G6: 17.2 | H6: 6.9 | I6: 3 | J6: 3 | K6: No | L6: Car | M6: 0 | N6: None | O6: 86.8
A7: ITI-1138 | B7: Cairo | C7: UI/UX | D7: Male | E7: 22 | F7: 8.5 | G7: 29.6 | H7: 5.2 | I7: 4 | J7: 2 | K7: Yes | L7: Microbus | M7: 1 | N7: Running | O7: 59.1
A8: ITI-1210 | B8: Cairo | C8: Data Science | D8: Male | E8: 21 | F8: 20.4 | G8: 56.1 | H8: 6.2 | I8: 3 | J8: 5 | K8: Yes | L8: Bus | M8: 0 | N8: Football | O8: 92.5
A9: ITI-1046 | B9: Cairo | C9: Data Science | D9: Female | E9: 23 | F9: 14 | G9: 51.7 | H9: 7.4 | I9: 3 | J9: 3 | K9: Yes | L9: Bus | M9: 3 | N9: Football | O9: 72.6
A10: ITI-1159 | B10: Assiut | C10: Data Science | D10: Male | E10: 20 | F10: 17.6 | G10: 21.8 | H10: 6.1 | I10: 5 | J10: 4 | K10: Yes | L10: Walk | M10: 1 | N10: Swimming | O10: 88.6
A11: ITI-1248 | B11: Alexandria | C11: Data Science | D11: Male | E11: 22 | F11: 18.7 | G11: 15 | H11: 7.3 | I11: 4 | J11: 4 | K11: No | L11: Microbus | M11: 0 | N11: Basketball | O11: 84.9
A12: ITI-1184 | B12: Mansoura | C12: Web Development | D12: Female | E12: 23 | F12: 12.2 | G12: 58.2 | H12: 7.3 | I12: 7 | J12: 3 | K12: Yes | L12: Microbus | M12: 2 | O12: 71.9
A13: ITI-1042 | B13: Cairo | C13: Data Science | D13: Male | E13: 27 | F13: 21.9 | G13: 22.8 | H13: 6.7 | I13: 6 | J13: 5 | K13: Yes | L13: Bus | M13: 0 | N13: Basketball | O13: 87.7
A14: ITI-1228 | B14: Alexandria | C14: Web Development | D14: Female | E14: 20 | G14: 15.7 | H14: 6.1 | I14: 2 | J14: 5 | K14: Yes | L14: Car | M14: 0 | N14: Football | O14: 55.6
A15: ITI-1083 | B15: Cairo | C15: Data Science | D15: Male | E15: 23 | F15: 12.3 | G15: 39.2 | H15: 6.3 | I15: 5 | J15: 5 | K15: Yes | L15: Bus | M15: 0 | N15: Running | O15: 78.6
A16: ITI-1166 | B16: Alexandria | C16: Web Development | D16: Male | E16: 26 | F16: 13.1 | G16: 63.8 | H16: 7.9 | I16: 1 | J16: 5 | K16: Yes | L16: Bus | M16: 0 | N16: None | O16: 74.3
A17: ITI-1195 | B17: Mansoura | C17: UI/UX | D17: Female | E17: 25 | F17: 14.7 | G17: 13.6 | H17: 6.9 | I17: 4 | J17: 3 | K17: Yes | L17: Bus | M17: 0 | O17: 77.2
A18: ITI-1227 | B18: Alexandria | C18: Web Development | D18: Male | E18: 22 | F18: 16.6 | G18: 59.1 | H18: 7.5 | I18: 2 | J18: 3 | K18: Yes | L18: Bus | M18: 0 | N18: Basketball | O18: 66.8
A19: ITI-1147 | B19: Cairo | C19: Data Science | D19: Female | E19: 20 | F19: 18.6 | G19: 44.3 | H19: 7 | I19: 6 | J19: 2 | K19: Yes | L19: Metro | M19: 0 | N19: Football | O19: 83.7
A20: ITI-1105 | B20: Alexandria | C20: Web Development | D20: Female | E20: 25 | F20: 25.9 | G20: 22.4 | H20: 7.1 | I20: 4 | J20: 3 | K20: Yes | L20: Bus | M20: 0 | N20: Running | O20: 87.4
A21: ITI-1061 | B21: Assiut | C21: Data Science | D21: Male | E21: 23 | F21: 24.3 | G21: 5 | H21: 6 | I21: 5 | J21: 5 | K21: No | L21: Metro | M21: 1 | N21: Football | O21: 91.6
A22: ITI-1222 | B22: Cairo | C22: Data Science | D22: Male | E22: 21 | F22: 21.2 | G22: 30.3 | H22: 7.2 | I22: 6 | J22: 5 | K22: Yes | L22: Walk | M22: 0 | N22: Football | O22: 90
A23: ITI-1109 | B23: Menoufia | C23: Data Science | D23: Male | E23: 23 | F23: 9.5 | G23: 43.9 | H23: 6.6 | I23: 3 | J23: 5 | K23: Yes | L23: Microbus | M23: 1 | N23: Basketball | O23: 77
A24: ITI-1047 | B24: Cairo | C24: Data Science | D24: Female | E24: 22 | F24: 6.4 | G24: 17.1 | H24: 7 | I24: 4 | J24: 3 | K24: Yes | L24: Metro | M24: 0 | N24: Football | O24: 66.9
A25: ITI-1043 | B25: Cairo | C25: UI/UX | D25: Female | E25: 24 | F25: 13.7 | G25: 111.7 | H25: 6.9 | I25: 1 | J25: 3 | K25: Yes | L25: Bus | M25: 2 | O25: 69.4
A26: ITI-1186 | B26: Cairo | C26: Embedded Systems | D26: Male | E26: 21 | F26: 18.3 | G26: 66.4 | H26: 8.7 | I26: 4 | J26: 3 | K26: Yes | L26: Bus | M26: 0 | O26: 85.7
A27: ITI-1010 | B27: Menoufia | C27: Data Science | D27: Female | E27: 24 | F27: 25.7 | G27: 10.8 | H27: 6.1 | I27: 3 | J27: 4 | K27: Yes | L27: Walk | M27: 2 | N27: None | O27: 80.3
A28: ITI-1023 | B28: Menoufia | C28: Web Development | D28: Male | E28: 24 | F28: 21.5 | G28: 8.4 | H28: 7 | I28: 7 | J28: 5 | K28: Yes | L28: Bus | M28: 1 | N28: None | O28: 91.7
A29: ITI-1200 | B29: Alexandria | C29: Web Development | D29: Male | E29: 23 | G29: 35.2 | H29: 6.6 | I29: 3 | J29: 3 | K29: Yes | L29: Walk | M29: 1 | N29: Football | O29: 75.3
A30: ITI-1110 | B30: Mansoura | C30: Web Development | D30: Female | E30: 20 | F30: 9.3 | G30: 31 | H30: 6.7 | I30: 1 | J30: 4 | K30: No | L30: Car | M30: 0 | N30: Running | O30: 74.6
A31: ITI-1025 | B31: Mansoura | C31: Data Science | D31: Male | E31: 20 | F31: 17.7 | G31: 43.8 | H31: 6.8 | I31: 7 | J31: 4 | K31: Yes | L31: Walk | M31: 0 | N31: Swimming | O31: 77.2
A32: ITI-1114 | B32: Mansoura | C32: Data Science | D32: Female | E32: 29 | F32: 18.8 | G32: 16.2 | H32: 5.7 | I32: 0 | J32: 3 | K32: No | L32: Metro | M32: 1 | N32: Running | O32: 76.6
A33: ITI-1069 | B33: Cairo | C33: UI/UX | D33: Male | E33: 24 | F33: 16.5 | G33: 83 | H33: 8.1 | I33: 2 | J33: 4 | K33: Yes | L33: Metro | M33: 0 | O33: 90
A34: ITI-1145 | B34: Menoufia | C34: Web Development | D34: Male | F34: 15.7 | G34: 52.6 | H34: 6.4 | I34: 2 | J34: 3 | K34: No | L34: Bus | M34: 1 | N34: Swimming | O34: 85.1
A35: ITI-1225 | B35: Mansoura | C35: Data Science | D35: Male | E35: 25 | F35: 17.9 | G35: 12.2 | H35: 6.3 | I35: 3 | J35: 4 | K35: Yes | L35: Bus | M35: 0 | N35: Swimming | O35: 84.2
A36: ITI-1253 | B36: Cairo | C36: UI/UX | D36: Female | E36: 28 | F36: 9.8 | G36: 27.2 | H36: 7.8 | I36: 2 | J36: 2 | K36: Yes | L36: Microbus | M36: 0 | N36: Running | O36: 71
A37: ITI-1007 | B37: Alexandria | C37: Embedded Systems | D37: Male | E37: 24 | F37: 19.7 | G37: 31.9 | H37: 7.6 | I37: 1 | J37: 4 | K37: Yes | L37: Bus | M37: 0 | N37: Running | O37: 90.3
A38: ITI-1121 | B38: Cairo | C38: Data Science | D38: Female | E38: 23 | F38: 12.7 | G38: 11.6 | H38: 6 | I38: 5 | J38: 2 | K38: No | L38: Microbus | M38: 0 | N38: Football | O38: 78.3
A39: ITI-1068 | B39: Menoufia | C39: Data Science | D39: Male | E39: 25 | F39: 16.6 | G39: 44.1 | H39: 6.6 | I39: 3 | J39: 5 | K39: No | L39: Bus | M39: 0 | N39: Football | O39: 79.5
A40: ITI-1120 | B40: Assiut | C40: Data Science | D40: Female | E40: 21 | F40: 14.1 | G40: 18.5 | H40: 8.1 | I40: 3 | J40: 5 | K40: Yes | L40: Car | M40: 0 | N40: Football | O40: 71.9
...

Sheet Cleaning_log
A1: We started with 271 rows and finished with 260 rows because we removed 11 duplicate student records, handled non-response missing values, corrected formatted strings, and dropped 20 impossible errors while retaining 15 genuine long-commute outliers.
A3: # | B3: Column affected | C3: Problem observed | D3: Rows affected | E3: Action taken | F3: Rule / justification
A4: 1 | B4: student_id | C4: 11 duplicate student records found | D4: 11 | E4: Removed duplicate rows, keeping first instance | F4: Duplicate student records distort statistics and must be removed.
A5: 2 | B5: branch | C5: Inconsistent text casing (cairo, CAIRO, Mansora) | D5: 7 | E5: Standardized to Title Case (Cairo, Mansoura) | F5: Categorical variables require consistent text formatting for grouping.
A6: 3 | B6: track | C6: Text formatting and spacing issues (web development, Data Science) | D6: 9 | E6: Cleaned to standard categories (Web Development, Data Science, etc.) | F6: Track names must strictly match defined standard options.
A7: 4 | B7: gender | C7: Abbreviated and lowercased gender labels (M, m, female, F) | D7: 13 | E7: Standardized to Male and Female | F7: Categorical gender values must be uniform across all entries.
A8: 5 | B8: has_laptop | C8: Non-standard responses (1, Y, NO, N, yes) | D8: 9 | E8: Converted all to Yes and No | F8: Standard binary responses are restricted to Yes / No.
A9: 6 | B9: transport | C9: Typos and casing variations (bus, METRO, micro bus, car) | D9: 8 | E9: Standardized to Bus, Metro, Microbus, Car, Walk | F9: Transport modes must be clean for categorical analysis.
A10: 7 | B10: All Columns | C10: Disguised missing values (?, NA, n/a, -, unknown) | D10: 9 | E10: Converted disguised text to true NaN | F10: Text representation of missing values interferes with statistical calculations.
A11: 8 | B11: Numeric Columns | C11: Numbers embedded with units or commas (31 min, 25.1 hours, 55,6) | D11: 19 | E11: Extracted numbers, replaced commas with dots, cast to numeric | F11: Text-formatted numbers prevent statistical operations like average or sum.
A12: 9 | B12: age | C12: Values outside valid 17–45 range (150, -1, 5, -1) | D12: 4 | E12: Set invalid values to NaN | F12: Ages outside 17–45 violate defined Data Dictionary limits.
A13: 10 | B13: study_hours_week | C13: Out-of-bounds study hours (-5, 200, -5) | D13: 3 | E13: Set invalid values to NaN | F13: Weekly study hours cannot be negative or exceed 80 hours.
A14: 11 | B14: sleep_hours | C14: Impossible sleep values (25.0, 25.0, 0.0, 0.0) | D14: 4 | E14: Set invalid values to NaN | F14: Sleep duration must lie strictly between 2 and 14 hours daily.
A15: 12 | B15: satisfaction_1to5 | C15: Scores exceeding scale limits (6, 7, 7) | D15: 3 | E15: Set invalid values to NaN | F15: Satisfaction score is restricted strictly to an ordinal scale of 1 to 5.
... A19: 16 | B19: favorite_sport | C19: Explicit "none" or "No sport" text alongside missing entries | D19: 29 | E19: Standardized text to "None", preserved missing as NaN | F19: Explicit "None" indicates no sports activity, distinct from unanswered fields.

Sheet Descriptive_Statistics
A1: PART C — Descriptive Statistics
A4: Statistics | B4: Fromula | C4: Result | D4: Unit
A5: Count (n) | B5: COUNT(commute_minutes) | C5: =COUNT(cleaned_data!$G$2:$G$261) -> 254 | D5: Students
A6: Mean | B6: AVERAGE(range) | C6: =AVERAGE(cleaned_data!$G$2:$G$261) -> 45.298425 | D6: minutes
A7: Median | B7: MEDIAN(range) | C7: =MEDIAN(cleaned_data!$G$2:$G$261) -> 33.05 | D7: minutes
A8: Mode | B8: MODE(range) [same as MODE.SNGL] | C8: =MODE(cleaned_data!$G$2:$G$261) -> 37.2 | D8: minutes
A9: Minimum | B9: MIN(range) | C9: =MIN(cleaned_data!$G$2:$G$261) -> 5 | D9: minutes
A10: Maximum | B10: MAX(range) | C10: =MAX(cleaned_data!$G$2:$G$261) -> 256.5 | D10: minutes
A11: Range (Max − Min) | B11: C10-C9 | C11: =C10-C9 -> 251.5 | D11: minutes
A12: Standard Deviation | B12: STDEV(range) | C12: =STDEV(cleaned_data!$G$2:$G$261) -> 39.577322 | D12: minutes
A13: Q1 | B13: QUARTILE(range,1) | C13: =QUARTILE(cleaned_data!$G$2:$G$261,1) -> 20.375 | D13: minutes
A14: Q3 | B14: QUARTILE(range,3) | C14: =QUARTILE(cleaned_data!$G$2:$G$261,3) -> 58.35 | D14: minutes
A15: IQR (Q3 − Q1) | B15: C14-C13 | C15: =C14-C13 -> 37.975 | D15: minutes
D16: minutes
A19: Mean − Median (gap) | C19: =C6-C7 -> 12.248425 | D19: minutes
A20: Distribution Shape (derived) | C20: =IF($C$6>$C$7,"Right-Skewed (Positive Skew)",IF($C$6<$C$7,"Left-Skewed (Negative Skew)","Symmetric")) -> Right-Skewed (Positive Skew)
A22: Max. repeat count of any single commute value | C22: {=MAX(COUNTIF(cleaned_data!$G$2:$G$261,cleaned_data!$G$2:$G$261))} -> 3 | D22: out of 254 | E22: 16.1
E23: 25.9
E24: 37.2
A25: Q: Which is larger — the mean or the median?
A28: Q: What does the difference between the mean and the median tell us?
A41: Q: Is the distribution symmetric, left-skewed, or right-skewed?
A49: Q: What does the distribution tell us about commute times?
A64: Histogram — Distribution of commute_minutes
A66: Bin (minutes) | B66: Lower Bound | C66: Upper Bound | D66: Frequency (students) | F66: =SUM(D67:D79) -> 254
A67: 0–20 | B67: 0 | C67: 20 | D67: =COUNTIFS(cleaned_data!$G$2:$G$261,">="&B67,cleaned_data!$G$2:$G$261,"<"&C67) -> 63
A68: 20–40 | B68: 20 | C68: 40 | D68: =COUNTIFS(cleaned_data!$G$2:$G$261,">="&B68,cleaned_data!$G$2:$G$261,"<"&C68) -> 91
A69: 40–60 | B69: 40 | C69: 60 | D69: =COUNTIFS(cleaned_data!$G$2:$G$261,">="&B69,cleaned_data!$G$2:$G$261,"<"&C69) -> 40
A70: 60–80 | B70: 60 | C70: 80 | D70: =COUNTIFS(cleaned_data!$G$2:$G$261,">="&B70,cleaned_data!$G$2:$G$261,"<"&C70) -> 32
A71: 80–100 | B71: 80 | C71: 100 | D71: =COUNTIFS(cleaned_data!$G$2:$G$261,">="&B71,cleaned_data!$G$2:$G$261,"<"&C71) -> 8
A72: 100–120 | B72: 100 | C72: 120 | D72: =COUNTIFS(cleaned_data!$G$2:$G$261,">="&B72,cleaned_data!$G$2:$G$261,"<"&C72) -> 6
A73: 120–140 | B73: 120 | C73: 140 | D73: =COUNTIFS(cleaned_data!$G$2:$G$261,">="&B73,cleaned_data!$G$2:$G$261,"<"&C73) -> 5
A74: 140–160 | B74: 140 | C74: 160 | D74: =COUNTIFS(cleaned_data!$G$2:$G$261,">="&B74,cleaned_data!$G$2:$G$261,"<"&C74) -> 2
A75: 160–180 | B75: 160 | C75: 180 | D75: =COUNTIFS(cleaned_data!$G$2:$G$261,">="&B75,cleaned_data!$G$2:$G$261,"<"&C75) -> 1
A76: 180–200 | B76: 180 | C76: 200 | D76: =COUNTIFS(cleaned_data!$G$2:$G$261,">="&B76,cleaned_data!$G$2:$G$261,"<"&C76) -> 2
A77: 200–220 | B77: 200 | C77: 220 | D77: =COUNTIFS(cleaned_data!$G$2:$G$261,">="&B77,cleaned_data!$G$2:$G$261,"<"&C77) -> 2
A78: 220–240 | B78: 220 | C78: 240 | D78: =COUNTIFS(cleaned_data!$G$2:$G$261,">="&B78,cleaned_data!$G$2:$G$261,"<"&C78) -> 1
A79: 240–260 | B79: 240 | C79: 260 | D79: =COUNTIFS(cleaned_data!$G$2:$G$261,">="&B79,cleaned_data!$G$2:$G$261,"<"&C79) -> 1
A88: How do we know it's a right-skewed?!
A95: Conclusion
...

Sheet Branch_Calculations
A1: HELPER SHEET — Branch-Level Calculations (feeds Descriptive_Statistics)
A2: All branch names below are pulled from cleaned_data. All statistics are computed with live formulas (no typed results).
A4: Branch | B4: Count (non-blank commute) | C4: Mean Commute (min) | D4: Median Commute (min) | E4: Std Dev Commute (min)
A5: Cairo | B5: =COUNTIFS(cleaned_data!$B$2:$B$261,$A5,cleaned_data!$G$2:$G$261,"<>"&"") -> 98 | C5: =AVERAGEIFS(cleaned_data!$G$2:$G$261,cleaned_data!$B$2:$B$261,$A5) -> 60.352041 | D5: {=MEDIAN(_xlfn._xlws.FILTER(cleaned_data!$G$2:$G$261,(cleaned_data!$B$2:$B$261=A5)*(cleaned_data!$G$2:$G$261<>"")))} -> 46.6 | E5: {=_xlfn.STDEV.S(_xlfn._xlws.FILTER(cleaned_data!$G$2:$G$261,(cleaned_data!$B$2:$B$261=A5)*(cleaned_data!$G$2:$G$261<>"")))} -> 44.871689
A6: Alexandria | B6: =COUNTIFS(cleaned_data!$B$2:$B$261,$A6,cleaned_data!$G$2:$G$261,"<>"&"") -> 52 | C6: =AVERAGEIFS(cleaned_data!$G$2:$G$261,cleaned_data!$B$2:$B$261,$A6) -> 43.9 | D6: {=MEDIAN(_xlfn._xlws.FILTER(cleaned_data!$G$2:$G$261,(cleaned_data!$B$2:$B$261=A6)*(cleaned_data!$G$2:$G$261<>"")))} -> 33.35 | E6: {=_xlfn.STDEV.S(_xlfn._xlws.FILTER(cleaned_data!$G$2:$G$261,(cleaned_data!$B$2:$B$261=A6)*(cleaned_data!$G$2:$G$261<>"")))} -> 37.357252
A7: Mansoura | B7: =COUNTIFS(cleaned_data!$B$2:$B$261,$A7,cleaned_data!$G$2:$G$261,"<>"&"") -> 42 | C7: =AVERAGEIFS(cleaned_data!$G$2:$G$261,cleaned_data!$B$2:$B$261,$A7) -> 32.259524 | D7: {=MEDIAN(_xlfn._xlws.FILTER(cleaned_data!$G$2:$G$261,(cleaned_data!$B$2:$B$261=A7)*(cleaned_data!$G$2:$G$261<>"")))} -> 27.7 | E7: {=_xlfn.STDEV.S(_xlfn._xlws.FILTER(cleaned_data!$G$2:$G$261,(cleaned_data!$B$2:$B$261=A7)*(cleaned_data!$G$2:$G$261<>"")))} -> 30.063973
A8: Menoufia | B8: =COUNTIFS(cleaned_data!$B$2:$B$261,$A8,cleaned_data!$G$2:$G$261,"<>"&"") -> 32 | C8: =AVERAGEIFS(cleaned_data!$G$2:$G$261,cleaned_data!$B$2:$B$261,$A8) -> 36.7625 | D8: {=MEDIAN(_xlfn._xlws.FILTER(cleaned_data!$G$2:$G$261,(cleaned_data!$B$2:$B$261=A8)*(cleaned_data!$G$2:$G$261<>"")))} -> 27.55 | E8: {=_xlfn.STDEV.S(_xlfn._xlws.FILTER(cleaned_data!$G$2:$G$261,(cleaned_data!$B$2:$B$261=A8)*(cleaned_data!$G$2:$G$261<>"")))} -> 36.872525
A9: Assiut | B9: =COUNTIFS(cleaned_data!$B$2:$B$261,$A9,cleaned_data!$G$2:$G$261,"<>"&"") -> 30 | C9: =AVERAGEIFS(cleaned_data!$G$2:$G$261,cleaned_data!$B$2:$B$261,$A9) -> 25.906667 | D9: {=MEDIAN(_xlfn._xlws.FILTER(cleaned_data!$G$2:$G$261,(cleaned_data!$B$2:$B$261=A9)*(cleaned_data!$G$2:$G$261<>"")))} -> 24.05 | E9: {=_xlfn.STDEV.S(_xlfn._xlws.FILTER(cleaned_data!$G$2:$G$261,(cleaned_data!$B$2:$B$261=A9)*(cleaned_data!$G$2:$G$261<>"")))} -> 16.127101
A10: Total | B10: =SUM(B5:B9) -> 254 | C10: =AVERAGE(cleaned_data!G2:G261) -> 45.298425
A11: Overall mean commute (all 254 valid rows) | D11: 45.298425
A12: Branch with HIGHEST mean commute | D12: =_xlfn.SINGLE(INDEX($A$5:$A$9,MATCH(MAX($C$5:$C$9),$C$5:$C$9,0))) -> Cairo
A13: Branch with LOWEST mean commute | D13: =_xlfn.SINGLE(INDEX($A$5:$A$9,MATCH(MIN($C$5:$C$9),$C$5:$C$9,0))) -> Assiut
A14: Branch with HIGHEST variability (Std Dev) | D14: =_xlfn.SINGLE(INDEX($A$5:$A$9,MATCH(MAX($E$5:$E$9),$E$5:$E$9,0))) -> Cairo
A15: Branch with LOWEST variability (Std Dev) | D15: =_xlfn.SINGLE(INDEX($A$5:$A$9,MATCH(MIN($E$5:$E$9),$E$5:$E$9,0))) -> Assiut
A17: Overall mean commute EXCLUDING the highest-mean branch | D17: =AVERAGEIFS(cleaned_data!$G$2:$G$261,cleaned_data!$B$2:$B$261,"<>"&$D$12) -> 35.841667
A18: Change in overall mean (Original − Excluding branch) | D18: =$D$11-$D$17 -> 9.4567585
A19: Percent change in overall mean | D19: =$D$18/$D$11 -> 0.20876572
